<?xml version="1.0"?>
<sdf version="1.8">       
        
        <model name='vehicle_blue' canonical_link='chassis'>

           
            <frame name="lidar_frame" attached_to='chassis'>
                    <pose>0.8 0 0.5 0 0 0</pose>
            </frame>
            <frame name="base_link" attached_to="chassis">
                    <pose>0 0 0 0 0 0</pose>
            </frame>



            <!--chassis-->
            <link name='chassis'>
                <pose relative_to='__model__'>0.5 0 0.4 0 0 0</pose>
                <inertial> <!--inertial properties of the link mass, inertia matix-->
                    <mass>1.14395</mass>
                    <inertia>
                        <ixx>3.5329</ixx>
                        <ixy>0</ixy>
                        <ixz>0</ixz>
                        <iyy>3.81317</iyy>
                        <iyz>0</iyz>
                        <izz>4.76646</izz>
                    </inertia>
                </inertial>
                <visual name='visual'>
                    <geometry>
                        <box>
                            <size>1.4 1.0 0.5</size>
                        </box>
                    </geometry>
                    <!--Color of the link-->
                    <material>
                        <ambient>0.0 0.0 1.0 1</ambient>
                        <diffuse>0.0 0.0 1.0 1</diffuse>
                        <specular>0.0 0.0 1.0 1</specular>
                    </material>
                </visual>
                <collision name='collision'>
                    <geometry>
                        <box>
                            <size>1.4 1.0 0.5</size>
                        </box>
                    </geometry>
                </collision>
                <sensor name="imu_sensor" type="imu">
                    <always_on>1</always_on>
                    <update_rate>1</update_rate>
                    <visualize>true</visualize>
                    <topic>imu</topic>
                </sensor>
                 
                <sensor name='gpu_lidar' type='gpu_lidar'>
                    <pose relative_to='lidar_frame'>0 0 0 0 0 0</pose>
                    <topic>/scan</topic>
                    <update_rate>5</update_rate>
                    <ray>
                        <scan>
                            <horizontal>
                                <samples>180</samples>
                                <resolution>1</resolution>
                                <min_angle>-1.396263</min_angle>
                                <max_angle>1.396263</max_angle>
                            </horizontal>
                            <vertical>
                                <samples>1</samples>
                                <resolution>0.01</resolution>
                                <min_angle>0</min_angle>
                                <max_angle>0</max_angle>
                            </vertical>
                        </scan>
                        <range>
                            <min>0.08</min>
                            <max>100.0</max>
                            <resolution>0.01</resolution>
                        </range>
                    </ray>
                    <always_on>1</always_on>
                    <visualize>true</visualize>
                </sensor>
                <!-- Contact (bumper) sensor -->
                <sensor name="bumper_contacts" type="contact">
                      <update_rate>50</update_rate>
                      <!-- Monitor this/these collision(s) for contacts -->
                      <contact>
                        <collision>collision</collision>
                        <!-- You can repeat <collision>…</collision> for more parts -->
                      </contact>
                      <!-- Gazebo Transport topic name -->
                      <topic>contacts</topic>
                      <always_on>true</always_on>
                      <visualize>false</visualize>
                </sensor>
            </link>

            <!--Left wheel-->
            <link name='left_wheel'>
                <pose relative_to="chassis">-0.2 0.6 0 -1.5707 0 0</pose> <!--angles are in radian-->
                <inertial>
                    <mass>1</mass>
                    <inertia>
                        <ixx>0.043333</ixx>
                        <ixy>0</ixy>
                        <ixz>0</ixz>
                        <iyy>0.043333</iyy>
                        <iyz>0</iyz>
                        <izz>0.08</izz>
                    </inertia>
                </inertial>
                <visual name='visual'>
                    <geometry>
                        <cylinder>
                            <radius>0.4</radius>
                            <length>0.2</length>
                        </cylinder>
                    </geometry>
                    <material>
                        <ambient>1.0 0.0 0.0 1</ambient>
                        <diffuse>1.0 0.0 0.0 1</diffuse>
                        <specular>1.0 0.0 0.0 1</specular>
                    </material>
                </visual>
                <collision name='collision'>
                    <geometry>
                        <cylinder>
                            <radius>0.4</radius>
                            <length>0.2</length>
                        </cylinder>
                    </geometry>
                </collision>
            </link>

            <!--The same as left wheel but with different position-->
            <link name='right_wheel'>
                <pose relative_to="chassis">-0.2 -0.6 0 -1.5707 0 0</pose> <!--angles are in radian-->
                <inertial>
                    <mass>1</mass>
                    <inertia>
                        <ixx>0.043333</ixx>
                        <ixy>0</ixy>
                        <ixz>0</ixz>
                        <iyy>0.043333</iyy>
                        <iyz>0</iyz>
                        <izz>0.08</izz>
                    </inertia>
                </inertial>
                <visual name='visual'>
                    <geometry>
                        <cylinder>
                            <radius>0.4</radius>
                            <length>0.2</length>
                        </cylinder>
                    </geometry>
                    <material>
                        <ambient>1.0 0.0 0.0 1</ambient>
                        <diffuse>1.0 0.0 0.0 1</diffuse>
                        <specular>1.0 0.0 0.0 1</specular>
                    </material>
                </visual>
                <collision name='collision'>
                    <geometry>
                        <cylinder>
                            <radius>0.4</radius>
                            <length>0.2</length>
                        </cylinder>
                    </geometry>
                </collision>
            </link>

            <!--arbitrary frame-->
            <frame name="caster_frame" attached_to='chassis'>
                <pose>0.8 0 -0.2 0 0 0</pose>
            </frame>

            <!--caster wheel-->
            <link name='caster'>
                <pose relative_to='caster_frame'>-0.5 0 0 0 0 0</pose>
                <inertial>
                    <mass>1</mass>
                    <inertia>
                        <ixx>0.016</ixx>
                        <ixy>0</ixy>
                        <ixz>0</ixz>
                        <iyy>0.016</iyy>
                        <iyz>0</iyz>
                        <izz>0.016</izz>
                    </inertia>
                </inertial>
                <visual name='visual'>
                    <geometry>
                        <sphere>
                            <radius>0.2</radius>
                        </sphere>
                    </geometry>
                    <material>
                        <ambient>0.0 1 0.0 1</ambient>
                        <diffuse>0.0 1 0.0 1</diffuse>
                        <specular>0.0 1 0.0 1</specular>
                    </material>
                </visual>
                <collision name='collision'>
                    <geometry>
                        <sphere>
                            <radius>0.2</radius>
                        </sphere>
                    </geometry>
                </collision>
            </link>

            <!--left wheel joint-->
            <joint name='left_wheel_joint' type='revolute'>
                <pose relative_to='left_wheel'/>
                <parent>chassis</parent>
                <child>left_wheel</child>
                <axis>
                    <xyz expressed_in='__model__'>0 1 0</xyz> <!--can be descired to any frame or even arbitrary frames-->
                    <limit>
                        <lower>-1.79769e+308</lower>    <!--negative infinity-->
                        <upper>1.79769e+308</upper>     <!--positive infinity-->
                    </limit>
                </axis>
            </joint>

            <!--right wheel joint-->
            <joint name='right_wheel_joint' type='revolute'>
                <pose relative_to='right_wheel'/>
                <parent>chassis</parent>
                <child>right_wheel</child>
                <axis>
                    <xyz expressed_in='__model__'>0 1 0</xyz>
                    <limit>
                        <lower>-1.79769e+308</lower>    <!--negative infinity-->
                        <upper>1.79769e+308</upper>     <!--positive infinity-->
                    </limit>
                </axis>
            </joint>

            <!--caster wheel joint--> <!--pose defult value is the child-->
            <joint name='caster_wheel' type='ball'>
                <parent>chassis</parent>
                <child>caster</child>
            </joint>


            <plugin filename="gz-sim-diff-drive-system"
                    name="gz::sim::systems::DiffDrive">
              <left_joint>left_wheel_joint</left_joint>
              <right_joint>right_wheel_joint</right_joint>
              <odometry_topic>/model/vehicle_blue/odometry</odometry_topic>
              <tf_topic>/tf</tf_topic>
              <frame_id>odom</frame_id>
              <child_frame_id>base_link</child_frame_id>
              
              <wheel_separation>1.2</wheel_separation>
              <wheel_radius>0.4</wheel_radius>
              <topic>cmd_vel</topic>
              <!-- pub rate -->
              <!--11/7 comment <odom_publish_frequency>30</odom_publish_frequency>
              
              <odometry_topic>/model/vehicle_blue/odometry</odometry_topic>
              <tf_topic>/tf</tf_topic>
              <frame_id>world</frame_id>
              <child_frame_id>chassis</child_frame_id>-->
              <!-- <odometry_topic>odom</odometry_topic>-->
            </plugin>
            <!-- 
            <plugin filename="gz-sim-odometry-publisher-system"
                     name="gz::sim::systems::OdometryPublisher">
               <odom_frame>odom</odom_frame>
               <robot_base_frame>base_link</robot_base_frame>
               <odom_topic>/model/vehicle_blue/odometry</odom_topic>
               <odom_publish_frequency>30</odom_publish_frequency>
               <dimensions>3</dimensions>
             </plugin>-->
   
        </model>
</sdf>